<?xml version="1.0"?>
<!-- This URDF was automatically created by SolidWorks to URDF Exporter! Originally created by Stephen Brawner (brawner@gmail.com) 
     Commit Version: 1.6.0-4-g7f85cfe  Build Version: 1.6.7995.38578
     For more information, please see http://wiki.ros.org/sw_urdf_exporter -->
<robot
  name="tandem_mani">

<!-- world link -->
  <link name="world"/>

  <joint name="joint_fix" type="fixed">
    <origin
      xyz="-0 -0 0"
      rpy="-1.5708 0 0" />
	<parent link="world"/>
	<child link="base_link"/>
  </joint>

  <link
    name="base_link">
    <inertial>
      <origin
        xyz="-0.00012418 -0.015731 3.7732E-05"
        rpy="0 0 0" />
      <mass
        value="0.14451" />
      <inertia
        ixx="7.7079E-05"
        ixy="3.1357E-08"
        ixz="1.3877E-08"
        iyy="0.00013443"
        iyz="2.3591E-08"
        izz="7.6836E-05" />
    </inertial>
    <visual>
      <origin
        xyz="0 0 0"
        rpy="0 0 0" />
      <geometry>
        <mesh
          filename="package://tandem_mani/meshes/base_link.STL" />
      </geometry>
      <material
        name="">
        <color
          rgba="1 1 1 1" />
      </material>
    </visual>
    <collision>
      <origin
        xyz="0 0 0"
        rpy="0 0 0" />
      <geometry>
        <mesh
          filename="package://tandem_mani/meshes/base_link.STL" />
      </geometry>
    </collision>
  </link>
  <link
    name="link1">
    <inertial>
      <origin
        xyz="-1.671E-05 -0.040968 -0.00054586"
        rpy="0 0 0" />
      <mass
        value="0.11786" />
      <inertia
        ixx="6.056E-05"
        ixy="-1.5829E-07"
        ixz="-1.1489E-07"
        iyy="4.9936E-05"
        iyz="-3.3143E-06"
        izz="6.8007E-05" />
    </inertial>
    <visual>
      <origin
        xyz="0 0 0"
        rpy="0 0 0" />
      <geometry>
        <mesh
          filename="package://tandem_mani/meshes/link1.STL" />
      </geometry>
      <material
        name="">
        <color
          rgba="1 1 1 1" />
      </material>
    </visual>
    <collision>
      <origin
        xyz="0 0 0"
        rpy="0 0 0" />
      <geometry>
        <mesh
          filename="package://tandem_mani/meshes/link1.STL" />
      </geometry>
    </collision>
  </link>
  <joint
    name="joint1"
    type="revolute">
    <origin
      xyz="-0.00015771 -0.0416 6.4042E-05"
      rpy="0 0 0" />
    <parent
      link="base_link" />
    <child
      link="link1" />
    <axis
      xyz="0 1 0" />
    <limit
      lower="-30"
      upper="30"
      effort="100"
      velocity="100" />
  </joint>
  <link
    name="link2">
    <inertial>
      <origin
        xyz="-0.057534 3.7398E-05 0.028177"
        rpy="0 0 0" />
      <mass
        value="0.086527" />
      <inertia
        ixx="3.7771E-05"
        ixy="6.0862E-08"
        ixz="8.3768E-07"
        iyy="4.1278E-05"
        iyz="-2.3986E-07"
        izz="3.1627E-05" />
    </inertial>
    <visual>
      <origin
        xyz="0 0 0"
        rpy="0 0 0" />
      <geometry>
        <mesh
          filename="package://tandem_mani/meshes/link2.STL" />
      </geometry>
      <material
        name="">
        <color
          rgba="1 1 1 1" />
      </material>
    </visual>
    <collision>
      <origin
        xyz="0 0 0"
        rpy="0 0 0" />
      <geometry>
        <mesh
          filename="package://tandem_mani/meshes/link2.STL" />
      </geometry>
    </collision>
  </link>
  <joint
    name="joint2"
    type="revolute">
    <origin
      xyz="0 -0.0512 -0.029"
      rpy="0 0 0" />
    <parent
      link="link1" />
    <child
      link="link2" />
    <axis
      xyz="0 0 -1" />
    <limit
      lower="-30"
      upper="30"
      effort="100"
      velocity="100" />
  </joint>
  <link
    name="link3">
    <inertial>
      <origin
        xyz="-0.080231 -3.4126E-05 -0.00028762"
        rpy="0 0 0" />
      <mass
        value="0.1099" />
      <inertia
        ixx="3.2676E-05"
        ixy="-1.9085E-07"
        ixz="-4.9253E-06"
        iyy="0.00010026"
        iyz="-8.1706E-08"
        izz="0.00010489" />
    </inertial>
    <visual>
      <origin
        xyz="0 0 0"
        rpy="0 0 0" />
      <geometry>
        <mesh
          filename="package://tandem_mani/meshes/link3.STL" />
      </geometry>
      <material
        name="">
        <color
          rgba="1 1 1 1" />
      </material>
    </visual>
    <collision>
      <origin
        xyz="0 0 0"
        rpy="0 0 0" />
      <geometry>
        <mesh
          filename="package://tandem_mani/meshes/link3.STL" />
      </geometry>
    </collision>
  </link>
  <joint
    name="joint3"
    type="revolute">
    <origin
      xyz="-0.0923 0 0.0285"
      rpy="0 0 0" />
    <parent
      link="link2" />
    <child
      link="link3" />
    <axis
      xyz="1 0 0" />
    <limit
      lower="-30"
      upper="30"
      effort="100"
      velocity="100" />
  </joint>
  <link
    name="link4">
    <inertial>
      <origin
        xyz="-0.12453 -2.9587E-05 0.028547"
        rpy="0 0 0" />
      <mass
        value="0.12676" />
      <inertia
        ixx="2.2633E-05"
        ixy="-2.8649E-07"
        ixz="-1.8437E-06"
        iyy="0.00024005"
        iyz="-1.7908E-08"
        izz="0.00025741" />
    </inertial>
    <visual>
      <origin
        xyz="0 0 0"
        rpy="0 0 0" />
      <geometry>
        <mesh
          filename="package://tandem_mani/meshes/link4.STL" />
      </geometry>
      <material
        name="">
        <color
          rgba="1 1 1 1" />
      </material>
    </visual>
    <collision>
      <origin
        xyz="0 0 0"
        rpy="0 0 0" />
      <geometry>
        <mesh
          filename="package://tandem_mani/meshes/link4.STL" />
      </geometry>
    </collision>
  </link>
  <joint
    name="joint4"
    type="revolute">
    <origin
      xyz="-0.0965 0 -0.0287"
      rpy="0 0 0" />
    <parent
      link="link3" />
    <child
      link="link4" />
    <axis
      xyz="0 0 -1" />
    <limit
      lower="-30"
      upper="30"
      effort="100"
      velocity="100" />
  </joint>
</robot>
