<?xml version="1.0" ?>
<sdf version='1.7'>
  <model name='tandem_mani'>
    <kinematic>1</kinematic>
    <link name='world'>
      <gravity>0</gravity>
      <kinematic>1</kinematic>
      <pose>0 0 0 0 -0 0</pose>
    </link>
    <link name='platform'>
      <pose>0 0 0 0 0 0</pose>
      <inertial>
        <mass>6</mass>
        <inertia>
          <ixx>2</ixx>
          <ixy>0</ixy>
          <ixz>0</ixz>
          <iyy>2</iyy>
          <iyz>0</iyz>
          <izz>2</izz>
        </inertia>
      </inertial>
      <self_collide>1</self_collide>
      <collision name='platform_collision'>
        <geometry>
          <box>
            <size>0.3 0.3 0.1</size>
          </box>
        </geometry>
      </collision>
      <visual name='platform_visual'>
        <geometry>
          <box>
            <size>0.3 0.3 0.1</size>
          </box>
        </geometry>
      </visual>
    </link>
    <joint name='platform_base_link' type='revolute'>
      <pose relative_to='platform'>0 0 0.05 3.1516 0 0</pose>
      <parent>platform</parent>
      <child>base_link</child>
      <axis>
        <xyz>0 0 1</xyz>
        <limit>
          <lower>0</lower>
          <upper>0</upper>
        </limit>
        <dynamics>
          <spring_reference>0</spring_reference>
          <spring_stiffness>0</spring_stiffness>
        </dynamics>
      </axis>
    </joint>
    <link name='base_link'>
      <pose relative_to='platform_base_link'>0 0 0 0 -0 0</pose>
      <inertial>
        <pose>0.000136 5.9e-05 -0.018366 0 -0 0</pose>
        <mass>0.28597</mass>
        <inertia>
          <ixx>0.000115724</ixx>
          <ixy>4.70433e-08</ixy>
          <ixz>-7.88346e-09</ixz>
          <iyy>0.000115479</iyy>
          <iyz>3.79749e-08</iyz>
          <izz>0.000181648</izz>
        </inertia>
      </inertial>
      <self_collide>1</self_collide>
      <enable_wind>0</enable_wind>
      <kinematic>0</kinematic>
      <collision name='base_link_collision'>
        <pose>0 0 0 0 -0 0</pose>
        <geometry>
          <mesh>
            <scale>1 1 1</scale>
            <uri>file:///home/ahao/tandem_mani/src/tandem_mani/meshes/base_link.STL</uri>
          </mesh>
        </geometry>
      </collision>
      <visual name='base_link_visual'>
        <pose>0 0 0 0 -0 0</pose>
        <geometry>
          <mesh>
            <scale>1 1 1</scale>
            <uri>file:///home/ahao/tandem_mani/src/tandem_mani/meshes/base_link.STL</uri>
          </mesh>
        </geometry>
      </visual>
    </link>
    <joint name='joint1' type='revolute'>
      <pose relative_to='base_link'>0.000158 6.4e-05 -0.093 0 -0 1.5708</pose>
      <parent>base_link</parent>
      <child>link1</child>
      <axis>
        <xyz>0 0 1</xyz>
        <limit>
          <lower>-1e+16</lower>
          <upper>1e+16</upper>
        </limit>
        <dynamics>
          <spring_reference>0</spring_reference>
          <spring_stiffness>0</spring_stiffness>
        </dynamics>
      </axis>
    </joint>
    <link name='link1'>
      <pose relative_to='joint1'>0 0 0 0 -0 0</pose>
      <inertial>
        <pose>-1.5e-05 -4.8e-05 0.00413 0 -0 0</pose>
        <mass>0.244954</mass>
        <inertia>
          <ixx>9.36608e-05</ixx>
          <ixy>6.38709e-08</ixy>
          <ixz>9.09639e-08</ixz>
          <iyy>0.000111053</iyy>
          <iyz>-2.21214e-06</iyz>
          <izz>8.44876e-05</izz>
        </inertia>
      </inertial>
      <self_collide>1</self_collide>
      <enable_wind>0</enable_wind>
      <kinematic>0</kinematic>
      <collision name='link1_collision'>
        <pose>0 0 0 0 -0 0</pose>
        <geometry>
          <mesh>
            <scale>1 1 1</scale>
            <uri>file:///home/ahao/tandem_mani/src/tandem_mani/meshes/link1.STL</uri>
          </mesh>
        </geometry>
      </collision>
      <visual name='link1_visual'>
        <pose>0 0 0 0 -0 0</pose>
        <geometry>
          <mesh>
            <scale>1 1 1</scale>
            <uri>file:///home/ahao/tandem_mani/src/tandem_mani/meshes/link1.STL</uri>
          </mesh>
        </geometry>
      </visual>
    </link>
    <joint name='joint2' type='revolute'>
      <pose relative_to='link1'>0 0 0 -1.57079 -1.57079 -3.14159</pose>
      <parent>link1</parent>
      <child>link2</child>
      <axis>
        <xyz>0 0 1</xyz>
        <limit>
          <lower>-1e+16</lower>
          <upper>1e+16</upper>
        </limit>
        <dynamics>
          <spring_reference>0</spring_reference>
          <spring_stiffness>0</spring_stiffness>
        </dynamics>
      </axis>
    </joint>
    <link name='link2'>
      <pose relative_to='joint2'>0 0 0 0 -0 0</pose>
      <inertial>
        <pose>-0 -0.065589 -0.000126 0 -0 0</pose>
        <mass>0.230125</mass>
        <inertia>
          <ixx>7.49193e-05</ixx>
          <ixy>-3.29441e-13</ixy>
          <ixz>-1.56145e-12</ixz>
          <iyy>8.19198e-05</iyy>
          <iyz>-5.7839e-07</iyz>
          <izz>6.85328e-05</izz>
        </inertia>
      </inertial>
      <self_collide>1</self_collide>
      <enable_wind>0</enable_wind>
      <kinematic>0</kinematic>
      <collision name='link2_collision'>
        <pose>0 0 0 0 -0 0</pose>
        <geometry>
          <mesh>
            <scale>1 1 1</scale>
            <uri>file:///home/ahao/tandem_mani/src/tandem_mani/meshes/link2.STL</uri>
          </mesh>
        </geometry>
      </collision>
      <visual name='link2_visual'>
        <pose>0 0 0 0 -0 0</pose>
        <geometry>
          <mesh>
            <scale>1 1 1</scale>
            <uri>file:///home/ahao/tandem_mani/src/tandem_mani/meshes/link2.STL</uri>
          </mesh>
        </geometry>
      </visual>
    </link>
    <joint name='joint3' type='revolute'>
      <pose relative_to='link2'>0 -0.189 0 1.5708 -0 0</pose>
      <parent>link2</parent>
      <child>link3</child>
      <axis>
        <xyz>0 0 -1</xyz>
        <limit>
          <lower>-1e+16</lower>
          <upper>1e+16</upper>
        </limit>
        <dynamics>
          <spring_reference>0</spring_reference>
          <spring_stiffness>0</spring_stiffness>
        </dynamics>
      </axis>
    </joint>
    <link name='link3'>
      <pose relative_to='joint3'>0 0 0 0 -0 0</pose>
      <inertial>
        <pose>5e-06 3.6e-05 -0.009246 0 -0 0</pose>
        <mass>0.249723</mass>
        <inertia>
          <ixx>0.000142402</ixx>
          <ixy>-2.70845e-08</ixy>
          <ixz>-5.97668e-09</ixz>
          <iyy>0.000154589</iyy>
          <iyz>-4.14191e-06</iyz>
          <izz>7.47273e-05</izz>
        </inertia>
      </inertial>
      <self_collide>1</self_collide>
      <enable_wind>0</enable_wind>
      <kinematic>0</kinematic>
      <collision name='link3_collision'>
        <pose>0 0 0 0 -0 0</pose>
        <geometry>
          <mesh>
            <scale>1 1 1</scale>
            <uri>file:///home/ahao/tandem_mani/src/tandem_mani/meshes/link3.STL</uri>
          </mesh>
        </geometry>
      </collision>
      <visual name='link3_visual'>
        <pose>0 0 0 0 -0 0</pose>
        <geometry>
          <mesh>
            <scale>1 1 1</scale>
            <uri>file:///home/ahao/tandem_mani/src/tandem_mani/meshes/link3.STL</uri>
          </mesh>
        </geometry>
      </visual>
    </link>
    <joint name='joint4' type='revolute'>
      <pose relative_to='link3'>0 0 0 0.554293 -1.57079 -2.15255</pose>
      <parent>link3</parent>
      <child>link4</child>
      <axis>
        <xyz>0 0 1</xyz>
        <limit>
          <lower>-1e+16</lower>
          <upper>1e+16</upper>
        </limit>
        <dynamics>
          <spring_reference>0</spring_reference>
          <spring_stiffness>0</spring_stiffness>
        </dynamics>
      </axis>
    </joint>
    <link name='link4'>
      <pose relative_to='joint4'>0 0 0 0 -0 0</pose>
      <inertial>
        <pose>0.140083 0 0.000271 0 -0 0</pose>
        <mass>0.254533</mass>
        <inertia>
          <ixx>5.97967e-05</ixx>
          <ixy>5.81843e-20</ixy>
          <ixz>6.60762e-07</ixz>
          <iyy>0.000250962</iyy>
          <iyz>-6.19785e-20</iyz>
          <izz>0.00027523</izz>
        </inertia>
      </inertial>
      <self_collide>1</self_collide>
      <enable_wind>0</enable_wind>
      <kinematic>0</kinematic>
      <collision name='link4_collision'>
        <pose>0 0 0 0 -0 0</pose>
        <geometry>
          <mesh>
            <scale>1 1 1</scale>
            <uri>file:///home/ahao/tandem_mani/src/tandem_mani/meshes/link4.STL</uri>
          </mesh>
        </geometry>
      </collision>
      <visual name='link4_visual'>
        <pose>0 0 0 0 -0 0</pose>
        <geometry>
          <mesh>
            <scale>1 1 1</scale>
            <uri>file:///home/ahao/tandem_mani/src/tandem_mani/meshes/link4.STL</uri>
          </mesh>
        </geometry>
      </visual>
    </link>
    <joint name='joint5' type='revolute'>
      <pose relative_to='link4'>0.157 0 0 0 -0 0</pose>
      <parent>link4</parent>
      <child>link5</child>
      <axis>
        <xyz>0 0 1</xyz>
        <limit>
          <lower>-1e+16</lower>
          <upper>1e+16</upper>
        </limit>
        <dynamics>
          <spring_reference>0</spring_reference>
          <spring_stiffness>0</spring_stiffness>
        </dynamics>
      </axis>
    </joint>
    <link name='link5'>
      <pose relative_to='joint5'>0 0 0 0 -0 0</pose>
      <inertial>
        <pose>-0 -0.039549 0.00038 0 -0 0</pose>
        <mass>0.0494024</mass>
        <inertia>
          <ixx>4.37835e-05</ixx>
          <ixy>-1.71637e-12</ixy>
          <ixz>1.57326e-13</ixz>
          <iyy>1.65286e-05</iyy>
          <iyz>5.1529e-07</iyz>
          <izz>3.59336e-05</izz>
        </inertia>
      </inertial>
      <self_collide>1</self_collide>
      <enable_wind>0</enable_wind>
      <kinematic>0</kinematic>
      <collision name='link5_collision'>
        <pose>0 0 0 0 -0 0</pose>
        <geometry>
          <mesh>
            <scale>1 1 1</scale>
            <uri>file:///home/ahao/tandem_mani/src/tandem_mani/meshes/link5.STL</uri>
          </mesh>
        </geometry>
      </collision>
      <visual name='link5_visual'>
        <pose>0 0 0 0 -0 0</pose>
        <geometry>
          <mesh>
            <scale>1 1 1</scale>
            <uri>file:///home/ahao/tandem_mani/src/tandem_mani/meshes/link5.STL</uri>
          </mesh>
        </geometry>
      </visual>
    </link>
    <joint name='end_joint' type='revolute'>
      <pose relative_to='link5'>0 -0.12 -0.0005 -2.69849 -1.57079 1.12769</pose>
      <parent>link5</parent>
      <child>end_point</child>
      <axis>
        <xyz>0 0 -1</xyz>
        <limit>
          <lower>0</lower>
          <upper>0</upper>
        </limit>
        <dynamics>
          <spring_reference>0</spring_reference>
          <spring_stiffness>0</spring_stiffness>
        </dynamics>
      </axis>
    </joint>
    <link name='end_point'>
      <pose relative_to='end_joint'>0 0 0 0 -0 0</pose>
      <inertial>
        <pose>-0 0 0.003124 0 -0 0</pose>
        <mass>0.000333383</mass>
        <inertia>
          <ixx>2.71619e-09</ixx>
          <ixy>-1.96455e-24</ixy>
          <ixz>-5.89399e-24</ixz>
          <iyy>2.71619e-09</iyy>
          <iyz>-4.54736e-24</iyz>
          <izz>4.44638e-09</izz>
        </inertia>
      </inertial>
      <self_collide>1</self_collide>
      <enable_wind>0</enable_wind>
      <kinematic>0</kinematic>
      <collision name='end_point_collision'>
        <pose>0 0 0 0 -0 0</pose>
        <geometry>
          <mesh>
            <scale>1 1 1</scale>
            <uri>file:///home/ahao/tandem_mani/src/tandem_mani/meshes/end_point.STL</uri>
          </mesh>
        </geometry>
      </collision>
      <visual name='end_point_visual'>
        <pose>0 0 0 0 -0 0</pose>
        <geometry>
          <mesh>
            <scale>1 1 1</scale>
            <uri>file:///home/ahao/tandem_mani/src/tandem_mani/meshes/end_point.STL</uri>
          </mesh>
        </geometry>
      </visual>
    </link>
    <static>0</static>
    <allow_auto_disable>1</allow_auto_disable>
    <plugin name="motor_plugin" filename="libmotor_plugin.so">
      <joint_name>joint1</joint_name>
    </plugin>
    <plugin name="motor_plugin" filename="libmotor_plugin.so">
      <joint_name>joint2</joint_name>
    </plugin>
    <plugin name="motor_plugin" filename="libmotor_plugin.so">
      <joint_name>joint3</joint_name>
    </plugin>
    <plugin name="motor_plugin" filename="libmotor_plugin.so">
      <joint_name>joint4</joint_name>
    </plugin>
    <plugin name="motor_plugin" filename="libmotor_plugin.so">
      <joint_name>joint5</joint_name>
    </plugin>
  </model>
</sdf>
