<?xml version="1.0" encoding="utf-8"?>
<!-- This URDF was automatically created by SolidWorks to URDF Exporter! Originally created by Stephen Brawner (brawner@gmail.com) 
     Commit Version: 1.6.0-4-g7f85cfe  Build Version: 1.6.7995.38578
     For more information, please see http://wiki.ros.org/sw_urdf_exporter -->
<robot
  name="tandem_mani">
<link name="world"/>

 <joint
    name="world_joint"
    type="fixed">
    <origin
      xyz="0 0 1.5"
      rpy="0 0 0" />
    <parent
      link="world" />
    <child
      link="base_link" />
  </joint>

  <link
    name="base_link">
    <inertial>
      <origin
        xyz="0.000135595388122672 5.91224063131307E-05 -0.018365850422852"
        rpy="0 0 0" />
      <mass
        value="2" />
      <inertia
        ixx="2"
        ixy="0"
        ixz="0"
        iyy="2"
        iyz="0"
        izz="2" />
    </inertial>
    <visual>
      <origin
        xyz="0 0 0"
        rpy="0 0 0" />
      <geometry>
        <mesh
          filename="package://tandem_mani/meshes/base_link.STL" />
      </geometry>
      <material
        name="">
        <color
          rgba="1 1 1 1" />
      </material>
    </visual>
    <collision>
      <origin
        xyz="0 0 0"
        rpy="0 0 0" />
      <geometry>
        <mesh
          filename="package://tandem_mani/meshes/base_link.STL" />
      </geometry>
    </collision>
  </link>
  <link
    name="link1">
    <inertial>
      <origin
        xyz="-1.45218249936463E-05 -4.78850872871073E-05 0.0041298276795592"
        rpy="0 0 0" />
      <mass
        value="2" />
      <inertia
        ixx="2"
        ixy="0"
        ixz="0"
        iyy="2"
        iyz="0"
        izz="2" />
    </inertial>
    <visual>
      <origin
        xyz="0 0 0"
        rpy="0 0 0" />
      <geometry>
        <mesh
          filename="package://tandem_mani/meshes/link1.STL" />
      </geometry>
      <material
        name="">
        <color
          rgba="0.905882352941176 1 0.964705882352941 1" />
      </material>
    </visual>
    <collision>
      <origin
        xyz="0 0 0"
        rpy="0 0 0" />
      <geometry>
        <mesh
          filename="package://tandem_mani/meshes/link1.STL" />
      </geometry>
    </collision>
  </link>
  <joint
    name="joint1"
    type="revolute">
    <origin
      xyz="0.00015793 0 -0.093"
      rpy="0 0 1.5708" />
    <parent
      link="base_link" />
    <child
      link="link1" />
     <limit effort="500" velocity="100" lower="-3.14" upper="3.14" />
    <axis
      xyz="0 0 1" />
  </joint>
  <link
    name="link2">
    <inertial>
      <origin
        xyz="-2.14601662783948E-07 -0.0655891331164192 -0.000125674296825215"
        rpy="0 0 0" />
      <mass
        value="2" />
      <inertia
        ixx="2"
        ixy="0"
        ixz="0"
        iyy="2"
        iyz="0"
        izz="2" />
    </inertial>
    <visual>
      <origin
        xyz="0 0 0"
        rpy="0 0 0" />
      <geometry>
        <mesh
          filename="package://tandem_mani/meshes/link2.STL" />
      </geometry>
      <material
        name="">
        <color
          rgba="0.752941176470588 0.752941176470588 0.752941176470588 1" />
      </material>
    </visual>
    <collision>
      <origin
        xyz="0 0 0"
        rpy="0 0 0" />
      <geometry>
        <mesh
          filename="package://tandem_mani/meshes/link2.STL" />
      </geometry>
    </collision>
  </link>
  <joint
    name="joint2"
    type="revolute">
    <origin
      xyz="0 0 0"
      rpy="1.5708 0 0" />
    <parent
      link="link1" />
    <child
      link="link2" />
    <limit effort="500" velocity="100" lower="-3.14" upper="3.14" />
    <axis
      xyz="0 0 1" />
  </joint>
  <link
    name="link3">
    <inertial>
      <origin
        xyz="5.06666183667029E-06 3.62276375425394E-05 -0.00924645090381562"
        rpy="0 0 0" />
      <mass
        value="2" />
      <inertia
        ixx="2"
        ixy="0"
        ixz="0"
        iyy="2"
        iyz="0"
        izz="2" />
    </inertial>
    <visual>
      <origin
        xyz="0 0 0"
        rpy="0 0 0" />
      <geometry>
        <mesh
          filename="package://tandem_mani/meshes/link3.STL" />
      </geometry>
      <material
        name="">
        <color
          rgba="0.905882352941176 1 0.964705882352941 1" />
      </material>
    </visual>
    <collision>
      <origin
        xyz="0 0 0"
        rpy="0 0 0" />
      <geometry>
        <mesh
          filename="package://tandem_mani/meshes/link3.STL" />
      </geometry>
    </collision>
  </link>
  <joint
    name="joint3"
    type="revolute">
    <origin
      xyz="0 -0.189 0"
      rpy="1.5708 0 0" />
    <parent
      link="link2" />
    <child
      link="link3" />
    <limit effort="500" velocity="100" lower="-3.14" upper="3.14" />
    <axis
      xyz="0 0 1" />
  </joint>
  <link
    name="link4">
    <inertial>
      <origin
        xyz="0.140083180519364 7.70217223333702E-16 0.000270635189935343"
        rpy="0 0 0" />
     <mass
        value="2" />
      <inertia
        ixx="2"
        ixy="0"
        ixz="0"
        iyy="2"
        iyz="0"
        izz="2" />
    </inertial>
    <visual>
      <origin
        xyz="0 0 0"
        rpy="0 0 0" />
      <geometry>
        <mesh
          filename="package://tandem_mani/meshes/link4.STL" />
      </geometry>
      <material
        name="">
        <color
          rgba="0.752941176470588 0.752941176470588 0.752941176470588 1" />
      </material>
    </visual>
    <collision>
      <origin
        xyz="0 0 0"
        rpy="0 0 0" />
      <geometry>
        <mesh
          filename="package://tandem_mani/meshes/link4.STL" />
      </geometry>
    </collision>
  </link>
  <joint
    name="joint4"
    type="revolute">
    <origin
      xyz="0 0 0"
      rpy="-1.5708 -1.5708 0" />
    <parent
      link="link3" />
    <child
      link="link4" />
      <limit effort="500" velocity="100" lower="-3.14" upper="3.14" />
    <axis
      xyz="0 0 1" />
  </joint>
  <link
    name="link5">
    <inertial>
      <origin
        xyz="-1.65614616465248E-09 -0.0395485542653819 0.000379781564919621"
        rpy="0 0 0" />
     <mass
        value="2" />
      <inertia
        ixx="2"
        ixy="0"
        ixz="0"
        iyy="2"
        iyz="0"
        izz="2" />
    </inertial>
    <visual>
      <origin
        xyz="0 0 0"
        rpy="0 0 0" />
      <geometry>
        <mesh
          filename="package://tandem_mani/meshes/link5.STL" />
      </geometry>
      <material
        name="">
        <color
          rgba="0.792156862745098 0.819607843137255 0.933333333333333 1" />
      </material>
    </visual>
    <collision>
      <origin
        xyz="0 0 0"
        rpy="0 0 0" />
      <geometry>
        <mesh
          filename="package://tandem_mani/meshes/link5.STL" />
      </geometry>
    </collision>
  </link>
  <joint
    name="joint5"
    type="revolute">
    <origin
      xyz="0.157 0 0"
      rpy="0 0 1.5708" />
    <parent
      link="link4" />
    <child
      link="link5" />
    <limit effort="500" velocity="100" lower="-3.14" upper="3.14" />
    <axis
      xyz="0 0 1" />
  </joint>
  <link
    name="end_point">
    <inertial>
      <origin
        xyz="-1.38777878078145E-17 0 0.00312400364362017"
        rpy="0 0 0" />
     <mass
        value="0.000001" />
      <inertia
        ixx="1e-20"
        ixy="0"
        ixz="0"
        iyy="1e-20"
        iyz="0"
        izz="1e-20" />
    </inertial>
    <visual>
      <origin
        xyz="0 0 0"
        rpy="0 0 0" />
      <geometry>
        <mesh
          filename="package://tandem_mani/meshes/end_point.STL" />
      </geometry>
      <material
        name="">
        <color
          rgba="0.792156862745098 0.819607843137255 0.933333333333333 1" />
      </material>
    </visual>
    <collision>
      <origin
        xyz="0 0 0"
        rpy="0 0 0" />
      <geometry>
        <mesh
          filename="package://tandem_mani/meshes/end_point.STL" />
      </geometry>
    </collision>
  </link>
  <joint
    name="end_joint"
    type="revolute">
    <origin
      xyz="0 -0.12 -0.0005"
      rpy="-1.5708 -1.5708 0" />
    <parent
      link="link5" />
    <child
      link="end_point" />
    <limit effort="30" velocity="1" lower="-0.001" upper="0.001" />
    <axis
      xyz="0 0 1" />
  </joint>
</robot>
